Workbook

Sheet Data Extensions
A1: DE NAME | B1: Date Checked | C1: DictionaryLink | D1: SchemaLink | E1: . | F1: SFMCLastModifiedDate | G1: FieldCount | H1: RecordCount | I1: Sendable | J1: Testable | K1: Retention | L1: . | M1: Type | N1: Source | O1: SFID/SubKeyField | P1: . | Q1: HasInsertDate | R1: InsertDateField | S1: InsertDateNullable | T1: InsertDateDefault | U1: . | V1: Notes
A2: Active Handraisers - KPMG US Webform Submissions | B2: 46283 | C2: Active Handraisers - KPMG US Webform Submissions | D2: https://kpmgus.sharepoint.com/sites/US-Marketing_Data_Management/Lists/SFMC%20Data%20Dictionary/Attachments/43/Active%20Handraisers%20-%20KPMG%20US%20Webform%20Submissions.xlsx?web=1 | E2: . | F2: 46149 | G2: 59 | H2: 14870 | I2: No | J2: No | K2: Off | L2: . | M2: Filtered | N2: Centralized_Form_Processor_DE | O2: Salesforce_ID | P2: . | Q2: Y | R2: [Date] | S2: YES | T2: currentdate | U2: .
A3: BACKup_CFP | B3: 46283 | C3: BACKup_CFP | D3: https://kpmgus.sharepoint.com/sites/US-Marketing_Data_Management/Lists/SFMC%20Data%20Dictionary/Attachments/526/BACKup_CFP.xlsx?web=1 | E3: . | F3: 46149 | G3: 58 | H3: 170047 | I3: No | J3: No | K3: Off | L3: . | M3: Standard | O3: Salesforce_ID | P3: . | Q3: Y | R3: [Date] | S3: NO | T3: currentdate | U3: . | V3: Schema matches CFP default - 41 of 58 fields not used, Salesforce_ID not populated | W3: Type mismatch
A4: Centralized_Form _Journey | B4: 46283 | C4: Centralized_Form _Journey | D4: https://kpmgus.sharepoint.com/sites/US-Marketing_Data_Management/Lists/SFMC%20Data%20Dictionary/Attachments/44/Centralized_Form%20_Journey.xlsx?web=1 | E4: . | F4: 46055 | G4: 56 | H4: 73603 | I4: Yes | J4: No | K4: Off | L4: . | M4: Standard | O4: Salesforce_ID | P4: . | Q4: Y | R4: [Date] | S4: YES | T4: currentdate | U4: .
E5: . | L5: . | P5: . | U5: .
E6: . | L6: . | P6: . | U6: .
E7: . | L7: . | P7: . | U7: .
E8: . | L8: . | P8: . | U8: .
E9: . | L9: . | P9: . | U9: .
E10: . | L10: . | P10: . | U10: .
E11: . | L11: . | P11: . | U11: .
E12: . | L12: . | P12: . | U12: .
E13: . | L13: . | P13: . | U13: .
E14: . | L14: . | P14: . | U14: .
E15: . | L15: . | P15: . | U15: .
E16: . | L16: . | P16: . | U16: .
... E33: . | L33: . | P33: . | U33: .

Sheet Automations
A1: AutomationTitle | B1: AutoID | C1: Automation Name | D1: LastChecked | E1: BU | F1: A_Location | G1: A_Key | H1: A_Desc | I1: A_CreatedDate | J1: A_LastSavedDate | K1: A_LastPausedDate | L1: A_Status | M1: A_StartingSource | N1: A_ScheduleInfo | O1: A_FileLocation | P1: A_TriggerInfo | Q1: A_StepCount | R1: A_ErrorRate | S1: A_ErrorNotificationEmails | T1: A_HasErrorMonitor | U1: A_AvgRunTime | V1: A_Campaign | W1: A_NextRun | X1: A_LastRunStatus | Y1: A_LastRun | Z1: A_LastModified
A2: =CONCATENATE("A",TEXT(B2, "0000"),"__",C2) -> A01A__AutomationName | B2: 01A | C2: AutomationName | D2: n/a | E2: PROD | F2: my automations/ | I2: 46281 | J2: 46281 | K2: 46281 | M2: Schedule
A3: =CONCATENATE("A",TEXT(B3, "0000"),"__",C3) -> A09B__Consent-Consent Updates | B3: 09B | C3: Consent-Consent Updates | D3: 46296 | E3: PROD | F3: my automations/09. Preference/B.Daily | G3: 0f875206-cc21-4f9a-a4f5-40ebed2995cd | H3: Automation that processes consent status from SC. Also processes one click unsubscribe action. GEE-3391 | I3: 45422 | J3: 46296 | K3: 46289 | L3: Active | M3: Schedule | N3: Every 6 Hours | Q3: 53 | S3: us-dlbpgsfmcmonitoring@kpmg.com | T3: yes | W3: 46296.547
A4: =CONCATENATE("A",TEXT(B4, "0000"),"__",C4) -> A0000__Reporting-LinkedInLive_UpdateMasterDE | C4: Reporting-LinkedInLive_UpdateMasterDE | H4: N/A | M4: Awaiting Trigger
A5: =CONCATENATE("A",TEXT(B5, "0000"),"__",C5) -> A0000__SFIDUpdate-WebRFPGlobalMASTERDE | C5: SFIDUpdate-WebRFPGlobalMASTERDE | H5: Creates an automated task when a contact or lead submits the global RFP web form - GSENHANCEM-336 GSENHANCEM-335 | I5: 45392.502 | M5: Scheduled
A6: =CONCATENATE("A",TEXT(B6, "0000"),"__",C6) -> A0000__SFTaskCreation-GlobalRFPExistingContact | C6: SFTaskCreation-GlobalRFPExistingContact | H6: Update the Comment Field in the Sales Cloud -GSENHANCEM-336 | I6: 44665.08 | M6: Running
A7: =CONCATENATE("A",TEXT(B7, "0000"),"__",C7) -> A0000__CVENT-CventInviteExport | C7: CVENT-CventInviteExport | H7: Export of Cvent invitee information to MoveIt | I7: 44349.568 | M7: Scheduled
A8: =CONCATENATE("A",TEXT(B8, "0000"),"__",C8) -> A0000__Consent-UpdateAlumniOptIn | C8: Consent-UpdateAlumniOptIn | H8: Automation to process alumni opt ins and opt outs to keep the alumni status aligned in both marketing cloud and sales cloud. GEE-16210, GSENHANCEM-16669. | I8: 45304.386 | M8: Scheduled
A9: =CONCATENATE("A",TEXT(B9, "0000"),"__",C9) -> A0000__Consent-Consent Updates | C9: Consent-Consent Updates | H9: F | I9: 45422.319 | M9: Scheduled
A10: =CONCATENATE("A",TEXT(B10, "0000"),"__",C10) -> A0000__Suppression-HardBounceList | C10: Suppression-HardBounceList | H10: This automation captures the bounced records based on the Bopunce category, subcategory and SMTP code. It also updates the all subscribers status to held for the bounced records based on emails | I10: 44440.696 | M10: Scheduled
A11: =CONCATENATE("A",TEXT(B11, "0000"),"__",C11) -> A0000__InPersonEvent-AttendedTradeshowBoothScans | C11: InPersonEvent-AttendedTradeshowBoothScans | H11: Automated Process for In-Person Event Attended (Tradeshow Booth Scans) - GSENHANCEM-9628 | I11: 45197.758 | M11: Scheduled
A12: =CONCATENATE("A",TEXT(B12, "0000"),"__",C12) -> A0000__Subscribers-MarketingTeamResetAllSubscribersStatus | C12: Subscribers-MarketingTeamResetAllSubscribersStatus | H12: Reactivates subscribers by updating their status to Active based on email addresses from a Data Extension, with errors logged to Automation_Error_Log. GEE-18648 | I12: 45869.751 | M12: Scheduled
A13: =CONCATENATE("A",TEXT(B13, "0000"),"__",C13) -> A0000__SalesforceTaskCreation-EnrichmentTaskForActiveHandraisers | C13: SalesforceTaskCreation-EnrichmentTaskForActiveHandraisers | H13: This Automation fetches the records from the centralized processor DE and triggers the journey which creates the task on the sales cloud. | I13: 44783.368 | M13: Scheduled
A14: =CONCATENATE("A",TEXT(B14, "0000"),"__",C14) -> A0000__SFTaskCreation-MultipleInPersonAttendees | C14: SFTaskCreation-MultipleInPersonAttendees | H14: Automation for Multiple In-Person Attendees from the Same Account (Update ParentId as AccountId if not null else update AccountId) | I14: 45139.451 | M14: Scheduled
A15: =CONCATENATE("A",TEXT(B15, "0000"),"__",C15) -> A0000__SFIDUpdate-Maintain SalesforceID Marketing Data Sources | C15: SFIDUpdate-Maintain SalesforceID Marketing Data Sources | H15: Updates SalesforceID in 2nd and 3rd Party Source MASTER Data Extensions, as well as other key data extension such as Subscriber Preferences Email. | I15: 44470.451 | M15: Scheduled
A16: =CONCATENATE("A",TEXT(B16, "0000"),"__",C16) -> A0000__CentralizedFormProcessor-MasterQA | C16: CentralizedFormProcessor-MasterQA | H16: Identifies invalid campaign records, duplicates and incorrect preferences in Master_Centralized_Form Processor DE | I16: 45162.299 | M16: Scheduled
... A50: =CONCATENATE("A",TEXT(B50, "0000"),"__",C50) -> A0000__Reporting-SycndContactsLeadsUsers | C50: Reporting-SycndContactsLeadsUsers | H50: Combines Salesforce contacts, leads, and users into a unified dataset with standardized IDs and source labels; overwrites Syncd_ContactsLeadsUsers_FourBUs on each run. | I50: 44826.549 | M50: Scheduled
A51: =CONCATENATE("A",TEXT(B51, "0000"),"__",C51) -> A0000__Reporting-VendorContactDataKcentral_UpdateMasterDE | C51: Reporting-VendorContactDataKcentral_UpdateMasterDE | H51: N/A | M51: Awaiting Trigger
A52: =CONCATENATE("A",TEXT(B52, "0000"),"__",C52) -> A0000__Reporting-WebRFPGlobal_UpdateMasterDE | C52: Reporting-WebRFPGlobal_UpdateMasterDE | H52: N/A | M52: Awaiting Trigger
A53: =CONCATENATE("A",TEXT(B53, "0000"),"__",C53) -> A0000__Reporting-GA4Pageview_UpdateMasterDE | C53: Reporting-GA4Pageview_UpdateMasterDE | H53: N/A | M53: Awaiting Trigger
A54: =CONCATENATE("A",TEXT(B54, "0000"),"__",C54) -> A0000__Everest-EmailDeliverability_MonitoringGeneral | C54: Everest-EmailDeliverability_MonitoringGeneral | H54: N/A | M54: Awaiting Trigger
A55: =CONCATENATE("A",TEXT(B55, "0000"),"__",C55) -> A0000__Reporting-GA4DataOnboarding | C55: Reporting-GA4DataOnboarding | H55: N/A | M55: Awaiting Trigger
A56: =CONCATENATE("A",TEXT(B56, "0000"),"__",C56) -> A0000__Reporting-GlobalClicks | C56: Reporting-GlobalClicks | H56: Extracts click tracking data from the _Click data view, capturing engagement details such as URLs, domains, and subscriber activity; overwrites Global_Clicks DE on each run. | I56: 44669.579 | M56: Scheduled
A57: =CONCATENATE("A",TEXT(B57, "0000"),"__",C57) -> A0000__Reporting-Leads-ClosedStatusV2 | C57: Reporting-Leads-ClosedStatusV2 | H57: Extracts Salesforce leads with a closed status from Lead_Salesforce_5, capturing ID, email, and status details; overwrites Leads_Closed_Status_v2 DE on each run. | I57: 45436.408 | M57: Scheduled
A58: =CONCATENATE("A",TEXT(B58, "0000"),"__",C58) -> A0000__SFupdate-Emailchange_Invalid_Valid | C58: SFupdate-Emailchange_Invalid_Valid | H58: Extracts and evaluates Salesforce contact email records against invalid email suppression lists, identifying active invalid and recovery scenarios; overwrites intermediate and comparison DEs. | I58: 45077.439 | M58: Scheduled
A59: =CONCATENATE("A",TEXT(B59, "0000"),"__",C59) -> A0000__Reporting-GA4Event_UpdateMasterDE | C59: Reporting-GA4Event_UpdateMasterDE | H59: N/A | M59: Awaiting Trigger
A60: =CONCATENATE("A",TEXT(B60, "0000"),"__",C60) -> A0000__CentralizedFormProcessor-Extract | C60: CentralizedFormProcessor-Extract | H60: Extracts MCFP data and transfers the output file to FTP for downstream QA processing; runs daily to support centralized form data handling. | I60: 45538.252 | M60: Scheduled
A61: =CONCATENATE("A",TEXT(B61, "0000"),"__",C61) -> A0000__Everest-EmailDeliverability_UniqueEmailAddressMostRecentRunDate | C61: Everest-EmailDeliverability_UniqueEmailAddressMostRecentRunDate | H61: Extracts most recent Everest email deliverability records per email address from master data, capturing latest status and run details; overwrites EverestEmailDeliverability_Unique_MASTER on each run. | I61: 44635.602 | M61: Scheduled
A62: =CONCATENATE("A",TEXT(B62, "0000"),"__",C62) -> A0000__CVENT-Import | C62: CVENT-Import | H62: N/A | M62: Awaiting Trigger
A63: =CONCATENATE("A",TEXT(B63, "0000"),"__",C63) -> A0000__ExactTarget-JobIDCampaignID | C63: ExactTarget-JobIDCampaignID | H63: Extracts unique JobID and CampaignID pairs from MasterSendLog where CampaignID is present; overwrites ExactTargetJobIDCampaignID on each run. | I63: 44607.728 | M63: Scheduled
A64: =CONCATENATE("A",TEXT(B64, "0000"),"__",C64) -> A0000__Reporting-TaxBenchmarkingInprogres_UpdateMasterDE | C64: Reporting-TaxBenchmarkingInprogres_UpdateMasterDE | H64: N/A | M64: Awaiting Trigger
A65: =CONCATENATE("A",TEXT(B65, "0000"),"__",C65) -> A0000__Reporting-IntradoActivity_UpdateMasterDE | C65: Reporting-IntradoActivity_UpdateMasterDE | H65: N/A | M65: Awaiting Trigger
A66: =CONCATENATE("A",TEXT(B66, "0000"),"__",C66) -> A0000__Reporting-TaxBenchmarkingCompleted_Import | C66: Reporting-TaxBenchmarkingCompleted_Import | H66: N/A | M66: Awaiting Trigger
A67: =CONCATENATE("A",TEXT(B67, "0000"),"__",C67) -> A0000__Reporting-ExeEdu-OnlineClassCompletion | C67: Reporting-ExeEdu-OnlineClassCompletion | H67: N/A | M67: Awaiting Trigger
A68: =CONCATENATE("A",TEXT(B68, "0000"),"__",C68) -> A0000__Reporting-PIERegAttended_UpdateMasterDE | C68: Reporting-PIERegAttended_UpdateMasterDE | H68: N/A | M68: Awaiting Trigger
A69: =CONCATENATE("A",TEXT(B69, "0000"),"__",C69) -> A0000__Reporting-FileImportUT | C69: Reporting-FileImportUT | H69: N/A | M69: Awaiting Trigger
A70: =CONCATENATE("A",TEXT(B70, "0000"),"__",C70) -> A0000__Reporting-Intrado-Cleanup | C70: Reporting-Intrado-Cleanup | H70: N/A | I70: 46000.339 | M70: Scheduled
A71: =CONCATENATE("A",TEXT(B71, "0000"),"__",C71) -> A0000__Suppression-InvalidEmail_MASTER | C71: Suppression-InvalidEmail_MASTER | H71: Extracts and consolidates invalid and risky email addresses from Everest and ExactTarget data, enriching with Salesforce IDs; overwrites and updates InvalidEmail_MASTER_Suppression on each run. | I71: 44641.456 | M71: Scheduled
A72: =CONCATENATE("A",TEXT(B72, "0000"),"__",C72) -> A0000__Suppression-InvalidEmail_CPEUsageType | C72: Suppression-InvalidEmail_CPEUsageType | H72: Identifies and classifies invalid email usage types by comparing Salesforce contact email data with suppression sources; overwrites InvalidEmail_MASTER_Suppression_CPEUsageType on each run. | I72: 44755.379 | M72: Scheduled
A73: =CONCATENATE("A",TEXT(B73, "0000"),"__",C73) -> A0000__Segmentation-ReEngage | C73: Segmentation-ReEngage | H73: N/A | M73: Awaiting Trigger
...

Sheet AutoREF
A1: FIELD NAME | B1: DESCRIPTION | C1: LOCATION
A2: AutomationTitle | B2: DO NOT UPDATE
A3: AutoID | B3: DO NOT UPDATE
A4: Automation Name | B4: AutomationName | C4: Automation Home
A5: LastChecked | B5: Today's Date
A6: BU | B6: Business Unit - PROD, DEV, etc
A7: A_Location | B7: Folder location in SFMC | C7: Automation Summary Tab
A8: A_Key | C8: Automation Summary Tab
A9: A_Desc | B9: Type of Filetype inside of SFMC | C9: Automation Summary Tab
A10: A_CreatedDate | B10: AssetID (5 digit #) | C10: Automation Summary Tab
A11: A_LastSavedDate | B11: Published/Unpublished | C11: Automation Summary Tab
A12: A_LastPausedDate | B12: Created Date | C12: Automation Summary Tab
A13: A_Status | C13: Automation Workflow Tab
A14: A_StartingSource | B14: Schedule / Import / Trigger | C14: Automation Workflow Tab
A15: A_ScheduleInfo | C15: Automation Workflow Tab
A16: A_FileLocation | C16: Automation Workflow Tab
A17: A_TriggerInfo | C17: Automation Workflow Tab
A18: A_StepCount | C18: Automation Workflow Tab
A19: A_ErrorRate | C19: Automation Activity Tab
A20: A_ErrorNotificationEmails | C20: Automation Activity Tab
A21: A_HasErrorMonitor | B21: Does the email list contain a Monitoring Distribution Email Address | C21: Automation Activity Tab
A22: A_AvgRunTime | C22: Automation Activity Tab
A23: A_Campaign | C23: Automation Home
A24: A_NextRun | C24: Automation Home
A25: A_LastRunStatus | C25: Automation Home
A26: A_LastRun | C26: Automation Home
A27: A_LastModified | C27: Automation Home

Sheet MAP_DE_ACT_SQL
A1: MapDEID | B1: ActType | C1: ActStep | D1: ActivityName | E1: DEName | F1: Q_LN | G1: Type | H1: MainActionType | I1: CodeSyntax | J1: ActionCode | K1: DEPurpose | L1: JoinTo | M1: JoinOn_S | N1: JoinOn_J
A2: =CONCATENATE($C2,"_Ln",TEXT($F2,"000"),"_",$G2,"__",$E2) -> Flip_Unsubscribe_To_Active_For_Lead_Ln000_DE__Flip_All_Subscriber_Unsubscribe_to_Active | B2: =VLOOKUP($D2,Activities!$D:$G,3,FALSE) -> SQL | C2: =VLOOKUP($D2,Activities!$D:$G,2,FALSE) -> Flip_Unsubscribe_To_Active_For_Lead | D2: 1.1__Flip_Unsubscribe_To_Active_For_Lead__SQL | E2: Flip_All_Subscriber_Unsubscribe_to_Active | F2: 0 | G2: DE | H2: TargetDE | I2: SQL | J2: Overwrite | K2: TargetDE
A3: =CONCATENATE($C3,"_Ln",TEXT($F3,"000"),"_",$G3,"__",$E3) -> Flip_Unsubscribe_To_Active_For_Lead_Ln012_SDE__KPMG_Individual_Firm_Details__c_Salesforce_3 | B3: =VLOOKUP($D3,Activities!$D:$G,3,FALSE) -> SQL | C3: =VLOOKUP($D3,Activities!$D:$G,2,FALSE) -> Flip_Unsubscribe_To_Active_For_Lead | D3: 1.1__Flip_Unsubscribe_To_Active_For_Lead__SQL | E3: KPMG_Individual_Firm_Details__c_Salesforce_3 | F3: 12 | G3: SDE | H3: Source | I3: SQL | J3: FROM | K3: PrimarySource
A4: =CONCATENATE($C4,"_Ln",TEXT($F4,"000"),"_",$G4,"__",$E4) -> Flip_Unsubscribe_To_Active_For_Lead_Ln014_SDE__ContactPointEmail_Salesforce_5 | B4: =VLOOKUP($D4,Activities!$D:$G,3,FALSE) -> SQL | C4: =VLOOKUP($D4,Activities!$D:$G,2,FALSE) -> Flip_Unsubscribe_To_Active_For_Lead | D4: 1.1__Flip_Unsubscribe_To_Active_For_Lead__SQL | E4: ContactPointEmail_Salesforce_5 | F4: 14 | G4: SDE | H4: Join | I4: SQL | J4: JOIN | K4: Join | L4: KPMG_Individual_Firm_Details__c_Salesforce_3 | M4: KPMG_LeadId__c | N4: KPMG_Lead_Contact_Id__c
A5: =CONCATENATE($C5,"_Ln",TEXT($F5,"000"),"_",$G5,"__",$E5) -> Flip_Unsubscribe_To_Active_For_Lead_Ln017_DV___Subscribers | B5: =VLOOKUP($D5,Activities!$D:$G,3,FALSE) -> SQL | C5: =VLOOKUP($D5,Activities!$D:$G,2,FALSE) -> Flip_Unsubscribe_To_Active_For_Lead | D5: 1.1__Flip_Unsubscribe_To_Active_For_Lead__SQL | E5: _Subscribers | F5: 17 | G5: DV | H5: Join | I5: SQL | J5: JOIN | K5: Join | L5: KPMG_Individual_Firm_Details__c_Salesforce_3 | M5: EmailAddress | N5: EmailAddress
A6: =CONCATENATE($C6,"_Ln",TEXT($F6,"000"),"_",$G6,"__",$E6) -> Flip_Unsubscribe_To_Active_For_Contact_Ln000_DE__Flip_All_Subscriber_Unsubscribe_to_Active | B6: =VLOOKUP($D6,Activities!$D:$G,3,FALSE) -> SQL | C6: =VLOOKUP($D6,Activities!$D:$G,2,FALSE) -> Flip_Unsubscribe_To_Active_For_Contact | D6: 2.1__Flip_Unsubscribe_To_Active_For_Contact__SQL | E6: Flip_All_Subscriber_Unsubscribe_to_Active | F6: 0 | G6: DE | H6: TargetDE | I6: SQL | J6: Update | K6: TargetDE
A7: =CONCATENATE($C7,"_Ln",TEXT($F7,"000"),"_",$G7,"__",$E7) -> Flip_Unsubscribe_To_Active_For_Contact_Ln012_SDE__KPMG_Individual_Firm_Details__c_Salesforce_3 | B7: =VLOOKUP($D7,Activities!$D:$G,3,FALSE) -> SQL | C7: =VLOOKUP($D7,Activities!$D:$G,2,FALSE) -> Flip_Unsubscribe_To_Active_For_Contact | D7: 2.1__Flip_Unsubscribe_To_Active_For_Contact__SQL | E7: KPMG_Individual_Firm_Details__c_Salesforce_3 | F7: 12 | G7: SDE | H7: Source | I7: SQL | J7: FROM | K7: PrimarySource
A8: =CONCATENATE($C8,"_Ln",TEXT($F8,"000"),"_",$G8,"__",$E8) -> Flip_Unsubscribe_To_Active_For_Contact_Ln014_SDE__ContactPointEmail_Salesforce_5 | B8: =VLOOKUP($D8,Activities!$D:$G,3,FALSE) -> SQL | C8: =VLOOKUP($D8,Activities!$D:$G,2,FALSE) -> Flip_Unsubscribe_To_Active_For_Contact | D8: 2.1__Flip_Unsubscribe_To_Active_For_Contact__SQL | E8: ContactPointEmail_Salesforce_5 | F8: 14 | G8: SDE | H8: Join | I8: SQL | J8: JOIN | K8: Join | L8: KPMG_Individual_Firm_Details__c_Salesforce_3 | M8: KPMG_ContactId__c | N8: KPMG_Lead_Contact_Id__c
A9: =CONCATENATE($C9,"_Ln",TEXT($F9,"000"),"_",$G9,"__",$E9) -> Flip_Unsubscribe_To_Active_For_Contact_Ln017_DV___Subscribers | B9: =VLOOKUP($D9,Activities!$D:$G,3,FALSE) -> SQL | C9: =VLOOKUP($D9,Activities!$D:$G,2,FALSE) -> Flip_Unsubscribe_To_Active_For_Contact | D9: 2.1__Flip_Unsubscribe_To_Active_For_Contact__SQL | E9: _Subscribers | F9: 17 | G9: DV | H9: Join | I9: SQL | J9: JOIN | K9: Join | L9: KPMG_Individual_Firm_Details__c_Salesforce_3 | M9: EmailAddress | N9: EmailAddress
A10: =CONCATENATE($C10,"_Ln",TEXT($F10,"000"),"_",$G10,"__",$E10) -> Final_Flip_All_Subscribers_To_Unsubscribe_To_Active_Ln000_DE__Final_Flip_All_Subscriber_Unsubscribe_To_Active | B10: =VLOOKUP($D10,Activities!$D:$G,3,FALSE) -> SQL | C10: =VLOOKUP($D10,Activities!$D:$G,2,FALSE) -> Final_Flip_All_Subscribers_To_Unsubscribe_To_Active | D10: 4.1__Final_Flip_All_Subscribers_To_Unsubscribe_To_Active__SQL | E10: Final_Flip_All_Subscriber_Unsubscribe_To_Active | F10: 0 | G10: DE | H10: TargetDE | I10: SQL | J10: Overwrite | K10: TargetDE
A11: =CONCATENATE($C11,"_Ln",TEXT($F11,"000"),"_",$G11,"__",$E11) -> Final_Flip_All_Subscribers_To_Unsubscribe_To_Active_Ln003_DE__Flip_All_Subscriber_Unsubscribe_to_Active | B11: =VLOOKUP($D11,Activities!$D:$G,3,FALSE) -> SQL | C11: =VLOOKUP($D11,Activities!$D:$G,2,FALSE) -> Final_Flip_All_Subscribers_To_Unsubscribe_To_Active | D11: 4.1__Final_Flip_All_Subscribers_To_Unsubscribe_To_Active__SQL | E11: Flip_All_Subscriber_Unsubscribe_to_Active | F11: 3 | G11: DE | H11: Source | I11: sQL | J11: FROM | K11: PrimarySource
A12: =CONCATENATE($C12,"_Ln",TEXT($F12,"000"),"_",$G12,"__",$E12) -> Optin_from_Unsubscribe_From_All_Preferences_Ln000_DE__Remove_Optin_Records_From_UnsubscribeFromAllPreferences | B12: =VLOOKUP($D12,Activities!$D:$G,3,FALSE) -> SQL | C12: =VLOOKUP($D12,Activities!$D:$G,2,FALSE) -> Optin_from_Unsubscribe_From_All_Preferences | D12: 8.1__ Optin_from_Unsubscribe_From_All_Preferences__SQL | E12: Remove_Optin_Records_From_UnsubscribeFromAllPreferences | F12: 0 | G12: DE | H12: TargetDE | I12: SQL | J12: Overwrite | K12: TargetDE
A13: =CONCATENATE($C13,"_Ln",TEXT($F13,"000"),"_",$G13,"__",$E13) -> Optin_from_Unsubscribe_From_All_Preferences_Ln015_DE__Flip_All_Subscriber_Unsubscribe_to_Active | B13: =VLOOKUP($D13,Activities!$D:$G,3,FALSE) -> SQL | C13: =VLOOKUP($D13,Activities!$D:$G,2,FALSE) -> Optin_from_Unsubscribe_From_All_Preferences | D13: 8.1__ Optin_from_Unsubscribe_From_All_Preferences__SQL | E13: Flip_All_Subscriber_Unsubscribe_to_Active | F13: 15 | G13: DE | H13: Source | I13: SQL | J13: FROM | K13: PrimarySource
A14: =CONCATENATE($C14,"_Ln",TEXT($F14,"000"),"_",$G14,"__",$E14) -> Optin_from_Unsubscribe_From_All_Preferences_Ln017_DE__Unsubscribe_From_All_Preferences | B14: =VLOOKUP($D14,Activities!$D:$G,3,FALSE) -> SQL | C14: =VLOOKUP($D14,Activities!$D:$G,2,FALSE) -> Optin_from_Unsubscribe_From_All_Preferences | D14: 8.1__ Optin_from_Unsubscribe_From_All_Preferences__SQL | E14: Unsubscribe_From_All_Preferences | F14: 17 | G14: DE | H14: Join | I14: SQL | J14: JOIN | K14: Join | L14: Flip_All_Subscriber_Unsubscribe_to_Active | M14: EmailAddress | N14: EmailAddress
A15: =CONCATENATE($C15,"_Ln",TEXT($F15,"000"),"_",$G15,"__",$E15) -> Remaining_OptIn_Records_From_Unsubscribe_Ln000_DE__Remaining_Optin_Records_From_UnsubscribeFromAllPreferences | B15: =VLOOKUP($D15,Activities!$D:$G,3,FALSE) -> SQL | C15: =VLOOKUP($D15,Activities!$D:$G,2,FALSE) -> Remaining_OptIn_Records_From_Unsubscribe | D15: 10.1__Remaining_OptIn_Records_From_Unsubscribe__SQL | E15: Remaining_Optin_Records_From_UnsubscribeFromAllPreferences | F15: 0 | G15: DE | H15: TargetDE | I15: SQL | J15: Overwrite | K15: TargetDE
A16: =CONCATENATE($C16,"_Ln",TEXT($F16,"000"),"_",$G16,"__",$E16) -> Remaining_OptIn_Records_From_Unsubscribe_Ln006_DE__Remove_Optin_Records_From_UnsubscribeFromAllPreferences | B16: =VLOOKUP($D16,Activities!$D:$G,3,FALSE) -> SQL | C16: =VLOOKUP($D16,Activities!$D:$G,2,FALSE) -> Remaining_OptIn_Records_From_Unsubscribe | D16: 10.1__Remaining_OptIn_Records_From_Unsubscribe__SQL | E16: Remove_Optin_Records_From_UnsubscribeFromAllPreferences | F16: 6 | G16: DE | H16: Source | I16: SQL | J16: FROM | K16: PrimarySource
A17: =CONCATENATE($C17,"_Ln",TEXT($F17,"000"),"_",$G17,"__",$E17) -> Add_Sales_Cloud_Active_To_Audit_Preferences_For_Leads_Ln000_DE__Audit_Preferences | B17: =VLOOKUP($D17,Activities!$D:$G,3,FALSE) -> SQL | C17: =VLOOKUP($D17,Activities!$D:$G,2,FALSE) -> Add_Sales_Cloud_Active_To_Audit_Preferences_For_Leads | D17: 11.1__Add_Sales_Cloud_Active_To_Audit_Preferences_For_Leads__SQL | E17: Audit_Preferences | F17: 0 | G17: DE | H17: TargetDE | I17: SQL | J17: Append | K17: TargetDE
A18: =CONCATENATE($C18,"_Ln",TEXT($F18,"000"),"_",$G18,"__",$E18) -> Add_Sales_Cloud_Active_To_Audit_Preferences_For_Leads_Ln025_DE__Flip_All_Subscriber_Unsubscribe_to_Active | B18: =VLOOKUP($D18,Activities!$D:$G,3,FALSE) -> SQL | C18: =VLOOKUP($D18,Activities!$D:$G,2,FALSE) -> Add_Sales_Cloud_Active_To_Audit_Preferences_For_Leads | D18: 11.1__Add_Sales_Cloud_Active_To_Audit_Preferences_For_Leads__SQL | E18: Flip_All_Subscriber_Unsubscribe_to_Active | F18: 25 | G18: DE | H18: Source | I18: SQL | J18: FROM | K18: PrimarySource
A19: =CONCATENATE($C19,"_Ln",TEXT($F19,"000"),"_",$G19,"__",$E19) -> Add_Sales_Cloud_Active_To_Audit_Preferences_For_Leads_Ln027_SDE__KPMG_Individual_Firm_Details__c_Salesforce_3 | B19: =VLOOKUP($D19,Activities!$D:$G,3,FALSE) -> SQL | C19: =VLOOKUP($D19,Activities!$D:$G,2,FALSE) -> Add_Sales_Cloud_Active_To_Audit_Preferences_For_Leads | D19: 11.1__Add_Sales_Cloud_Active_To_Audit_Preferences_For_Leads__SQL | E19: KPMG_Individual_Firm_Details__c_Salesforce_3 | F19: 27 | G19: SDE | H19: Join | I19: SQL | J19: LEFT JOIN | K19: Join | L19: Flip_All_Subscriber_Unsubscribe_to_Active | M19: SalesforceID | N19: KPMG_LeadId__c
A20: =CONCATENATE($C20,"_Ln",TEXT($F20,"000"),"_",$G20,"__",$E20) -> Add_Sales_Cloud_Active_To_Audit_Preferences_For_Leads_Ln030_SDE__Lead_Salesforce_5 | B20: =VLOOKUP($D20,Activities!$D:$G,3,FALSE) -> SQL | C20: =VLOOKUP($D20,Activities!$D:$G,2,FALSE) -> Add_Sales_Cloud_Active_To_Audit_Preferences_For_Leads | D20: 11.1__Add_Sales_Cloud_Active_To_Audit_Preferences_For_Leads__SQL | E20: Lead_Salesforce_5 | F20: 30 | G20: SDE | H20: Join | I20: SQL | J20: LEFT JOIN | K20: Join | L20: KPMG_Individual_Firm_Details__c_Salesforce_3 | M20: KPMG_LeadId__c | N20: Id
A21: =CONCATENATE($C21,"_Ln",TEXT($F21,"000"),"_",$G21,"__",$E21) -> Add_Sales_Cloud_Active_To_Audit_Preferences_For_Contacts_Ln000_DE__Audit_Preferences | B21: =VLOOKUP($D21,Activities!$D:$G,3,FALSE) -> SQL | C21: =VLOOKUP($D21,Activities!$D:$G,2,FALSE) -> Add_Sales_Cloud_Active_To_Audit_Preferences_For_Contacts | D21: 12.1__Add_Sales_Cloud_Active_To_Audit_Preferences_For_Contacts__SQL | E21: Audit_Preferences | F21: 0 | G21: DE | H21: TargetDE | I21: SQL | J21: Append | K21: TargetDE
A22: =CONCATENATE($C22,"_Ln",TEXT($F22,"000"),"_",$G22,"__",$E22) -> Add_Sales_Cloud_Active_To_Audit_Preferences_For_Contacts_Ln025_DE__Flip_All_Subscriber_Unsubscribe_to_Active | B22: =VLOOKUP($D22,Activities!$D:$G,3,FALSE) -> SQL | C22: =VLOOKUP($D22,Activities!$D:$G,2,FALSE) -> Add_Sales_Cloud_Active_To_Audit_Preferences_For_Contacts | D22: 12.1__Add_Sales_Cloud_Active_To_Audit_Preferences_For_Contacts__SQL | E22: Flip_All_Subscriber_Unsubscribe_to_Active | F22: 25 | G22: DE | H22: Source | I22: SQL | J22: FROM | K22: PrimarySource
A23: =CONCATENATE($C23,"_Ln",TEXT($F23,"000"),"_",$G23,"__",$E23) -> Add_Sales_Cloud_Active_To_Audit_Preferences_For_Contacts_Ln027_SDE__KPMG_Individual_Firm_Details__c_Salesforce_3 | B23: =VLOOKUP($D23,Activities!$D:$G,3,FALSE) -> SQL | C23: =VLOOKUP($D23,Activities!$D:$G,2,FALSE) -> Add_Sales_Cloud_Active_To_Audit_Preferences_For_Contacts | D23: 12.1__Add_Sales_Cloud_Active_To_Audit_Preferences_For_Contacts__SQL | E23: KPMG_Individual_Firm_Details__c_Salesforce_3 | F23: 27 | G23: SDE | H23: Join | I23: SQL | J23: JOIN | K23: Join | L23: Flip_All_Subscriber_Unsubscribe_to_Active | M23: SalesforceID | N23: KPMG_ContactId__c
A24: =CONCATENATE($C24,"_Ln",TEXT($F24,"000"),"_",$G24,"__",$E24) -> Add_Sales_Cloud_Active_To_Audit_Preferences_For_Contacts_Ln030_SDE__Contact_Salesforce_5 | B24: =VLOOKUP($D24,Activities!$D:$G,3,FALSE) -> SQL | C24: =VLOOKUP($D24,Activities!$D:$G,2,FALSE) -> Add_Sales_Cloud_Active_To_Audit_Preferences_For_Contacts | D24: 12.1__Add_Sales_Cloud_Active_To_Audit_Preferences_For_Contacts__SQL | E24: Contact_Salesforce_5 | F24: 30 | G24: SDE | H24: Join | I24: SQL | J24: JOIN | K24: Join | L24: KPMG_Individual_Firm_Details__c_Salesforce_3 | M24: KPMG_ContactId__c | N24: Id
A25: =CONCATENATE($C25,"_Ln",TEXT($F25,"000"),"_",$G25,"__",$E25) -> Add_Sales_Cloud_Active_To_Record_Keeper_Ln000_DE__ConsentUpdates_Recordkeeper | B25: =VLOOKUP($D25,Activities!$D:$G,3,FALSE) -> SQL | C25: =VLOOKUP($D25,Activities!$D:$G,2,FALSE) -> Add_Sales_Cloud_Active_To_Record_Keeper | D25: 13.1__Add_Sales_Cloud_Active_To_Record_Keeper__SQL | E25: ConsentUpdates_Recordkeeper | F25: 0 | G25: DE | H25: TargetDE | I25: SQL | J25: Append | K25: TargetDE
A26: =CONCATENATE($C26,"_Ln",TEXT($F26,"000"),"_",$G26,"__",$E26) -> Add_Sales_Cloud_Active_To_Record_Keeper_Ln014_DE__Flip_All_Subscriber_Unsubscribe_to_Active | B26: =VLOOKUP($D26,Activities!$D:$G,3,FALSE) -> SQL | C26: =VLOOKUP($D26,Activities!$D:$G,2,FALSE) -> Add_Sales_Cloud_Active_To_Record_Keeper | D26: 13.1__Add_Sales_Cloud_Active_To_Record_Keeper__SQL | E26: Flip_All_Subscriber_Unsubscribe_to_Active | F26: 14 | G26: DE | H26: Source | I26: SQL | J26: FROM | K26: PrimarySource
A27: =CONCATENATE($C27,"_Ln",TEXT($F27,"000"),"_",$G27,"__",$E27) -> Add_Sales_Cloud_Active_To_Record_Keeper_Ln016_SDE__Lead_Salesforce_5 | B27: =VLOOKUP($D27,Activities!$D:$G,3,FALSE) -> SQL | C27: =VLOOKUP($D27,Activities!$D:$G,2,FALSE) -> Add_Sales_Cloud_Active_To_Record_Keeper | D27: 13.1__Add_Sales_Cloud_Active_To_Record_Keeper__SQL | E27: Lead_Salesforce_5 | F27: 16 | G27: SDE | H27: Join | I27: SQL | J27: LEFT JOIN | K27: Join | L27: Flip_All_Subscriber_Unsubscribe_to_Active | M27: SalesforceID | N27: Id
A28: =CONCATENATE($C28,"_Ln",TEXT($F28,"000"),"_",$G28,"__",$E28) -> Add_Sales_Cloud_Active_To_Record_Keeper_Ln019_SDE__Contact_Salesforce_5 | B28: =VLOOKUP($D28,Activities!$D:$G,3,FALSE) -> SQL | C28: =VLOOKUP($D28,Activities!$D:$G,2,FALSE) -> Add_Sales_Cloud_Active_To_Record_Keeper | D28: 13.1__Add_Sales_Cloud_Active_To_Record_Keeper__SQL | E28: Contact_Salesforce_5 | F28: 19 | G28: SDE | H28: Join | I28: SQL | J28: LEFT JOIN | K28: Join | L28: Flip_All_Subscriber_Unsubscribe_to_Active | M28: SalesforceID | N28: Id
A29: =CONCATENATE($C29,"_Ln",TEXT($F29,"000"),"_",$G29,"__",$E29) -> Flip_Active_To_Unsubscribe_For_Lead_Ln000_DE__Preferences-Update_Unsubscribed_in_AllSubscribers | B29: =VLOOKUP($D29,Activities!$D:$G,3,FALSE) -> SQL | C29: =VLOOKUP($D29,Activities!$D:$G,2,FALSE) -> Flip_Active_To_Unsubscribe_For_Lead | D29: 15.1__Flip_Active_To_Unsubscribe_For_Lead__SQL | E29: Preferences-Update_Unsubscribed_in_AllSubscribers | F29: 0 | G29: DE | H29: TargetDE | I29: SQL | J29: Overwrite | K29: TargetDE
A30: =CONCATENATE($C30,"_Ln",TEXT($F30,"000"),"_",$G30,"__",$E30) -> Flip_Active_To_Unsubscribe_For_Lead_Ln008_SDE__KPMG_Individual_Firm_Details__c_Salesforce_3 | B30: =VLOOKUP($D30,Activities!$D:$G,3,FALSE) -> SQL | C30: =VLOOKUP($D30,Activities!$D:$G,2,FALSE) -> Flip_Active_To_Unsubscribe_For_Lead | D30: 15.1__Flip_Active_To_Unsubscribe_For_Lead__SQL | E30: KPMG_Individual_Firm_Details__c_Salesforce_3 | F30: 8 | G30: SDE | H30: Source | I30: SQL | J30: FROM | K30: PrimarySource
A31: =CONCATENATE($C31,"_Ln",TEXT($F31,"000"),"_",$G31,"__",$E31) -> Flip_Active_To_Unsubscribe_For_Lead_Ln010_SDE__ContactPointEmail_Salesforce_5 | B31: =VLOOKUP($D31,Activities!$D:$G,3,FALSE) -> SQL | C31: =VLOOKUP($D31,Activities!$D:$G,2,FALSE) -> Flip_Active_To_Unsubscribe_For_Lead | D31: 15.1__Flip_Active_To_Unsubscribe_For_Lead__SQL | E31: ContactPointEmail_Salesforce_5 | F31: 10 | G31: SDE | H31: Join | I31: SQL | J31: JOIN | K31: Join | L31: KPMG_Individual_Firm_Details__c_Salesforce_3 | M31: KPMG_LeadId__c | N31: KPMG_Lead_Contact_Id__c
A32: =CONCATENATE($C32,"_Ln",TEXT($F32,"000"),"_",$G32,"__",$E32) -> Flip_Active_To_Unsubscribe_For_Lead_Ln013_DV___Subscribers | B32: =VLOOKUP($D32,Activities!$D:$G,3,FALSE) -> SQL | C32: =VLOOKUP($D32,Activities!$D:$G,2,FALSE) -> Flip_Active_To_Unsubscribe_For_Lead | D32: 15.1__Flip_Active_To_Unsubscribe_For_Lead__SQL | E32: _Subscribers | F32: 13 | G32: DV | H32: Join | I32: SQL | J32: JOIN | K32: Join | L32: ContactPointEmail_Salesforce_5 | M32: EmailAddress | N32: EmailAddress
A33: =CONCATENATE($C33,"_Ln",TEXT($F33,"000"),"_",$G33,"__",$E33) -> Flip_Active_To_Unsubscribe_For_Contact_Ln000_DE__Preferences-Update_Unsubscribed_in_AllSubscribers | B33: =VLOOKUP($D33,Activities!$D:$G,3,FALSE) -> SQL | C33: =VLOOKUP($D33,Activities!$D:$G,2,FALSE) -> Flip_Active_To_Unsubscribe_For_Contact | D33: 16.1__Flip_Active_To_Unsubscribe_For_Contact__SQL | E33: Preferences-Update_Unsubscribed_in_AllSubscribers | F33: 0 | G33: DE | H33: TargetDE | I33: SQL | J33: Update | K33: TargetDE
A34: =CONCATENATE($C34,"_Ln",TEXT($F34,"000"),"_",$G34,"__",$E34) -> Flip_Active_To_Unsubscribe_For_Contact_Ln008_SDE__KPMG_Individual_Firm_Details__c_Salesforce_3 | B34: =VLOOKUP($D34,Activities!$D:$G,3,FALSE) -> SQL | C34: =VLOOKUP($D34,Activities!$D:$G,2,FALSE) -> Flip_Active_To_Unsubscribe_For_Contact | D34: 16.1__Flip_Active_To_Unsubscribe_For_Contact__SQL | E34: KPMG_Individual_Firm_Details__c_Salesforce_3 | F34: 8 | G34: SDE | H34: Source | I34: SQL | J34: FROM | K34: PrimarySource
A35: =CONCATENATE($C35,"_Ln",TEXT($F35,"000"),"_",$G35,"__",$E35) -> Flip_Active_To_Unsubscribe_For_Contact_Ln010_SDE__ContactPointEmail_Salesforce_5 | B35: =VLOOKUP($D35,Activities!$D:$G,3,FALSE) -> SQL | C35: =VLOOKUP($D35,Activities!$D:$G,2,FALSE) -> Flip_Active_To_Unsubscribe_For_Contact | D35: 16.1__Flip_Active_To_Unsubscribe_For_Contact__SQL | E35: ContactPointEmail_Salesforce_5 | F35: 10 | G35: SDE | H35: Join | I35: SQL | J35: JOIN | K35: Join | L35: KPMG_Individual_Firm_Details__c_Salesforce_3 | M35: KPMG_ContactId__c | N35: KPMG_Lead_Contact_Id__c
A36: =CONCATENATE($C36,"_Ln",TEXT($F36,"000"),"_",$G36,"__",$E36) -> Flip_Active_To_Unsubscribe_For_Contact_Ln013_DV___Subscribers | B36: =VLOOKUP($D36,Activities!$D:$G,3,FALSE) -> SQL | C36: =VLOOKUP($D36,Activities!$D:$G,2,FALSE) -> Flip_Active_To_Unsubscribe_For_Contact | D36: 16.1__Flip_Active_To_Unsubscribe_For_Contact__SQL | E36: _Subscribers | F36: 13 | G36: DV | H36: Join | I36: SQL | J36: JOIN | K36: Join | L36: ContactPointEmail_Salesforce_5 | M36: EmailAddress | N36: EmailAddress
A37: =CONCATENATE($C37,"_Ln",TEXT($F37,"000"),"_",$G37,"__",$E37) -> Final_Preferences-Update_Unsubscribed_in_AllSubscribers_Ln000_DE__Final_Preferences-Update_Unsubscribed_in_AllSubscribers | B37: =VLOOKUP($D37,Activities!$D:$G,3,FALSE) -> SQL | C37: =VLOOKUP($D37,Activities!$D:$G,2,FALSE) -> Final_Preferences-Update_Unsubscribed_in_AllSubscribers | D37: 17.1__Final_Preferences-Update_Unsubscribed_in_AllSubscribers__SQL | E37: Final_Preferences-Update_Unsubscribed_in_AllSubscribers | F37: 0 | G37: DE | H37: TargetDE | I37: SQL | J37: Overwrite | K37: TargetDE
A38: =CONCATENATE($C38,"_Ln",TEXT($F38,"000"),"_",$G38,"__",$E38) -> Final_Preferences-Update_Unsubscribed_in_AllSubscribers_Ln003_DE__Preferences-Update_Unsubscribed_in_AllSubscribers | B38: =VLOOKUP($D38,Activities!$D:$G,3,FALSE) -> SQL | C38: =VLOOKUP($D38,Activities!$D:$G,2,FALSE) -> Final_Preferences-Update_Unsubscribed_in_AllSubscribers | D38: 17.1__Final_Preferences-Update_Unsubscribed_in_AllSubscribers__SQL | E38: Preferences-Update_Unsubscribed_in_AllSubscribers | F38: 3 | G38: DE | H38: Source | I38: SQL | J38: FROM | K38: PrimarySource
A39: =CONCATENATE($C39,"_Ln",TEXT($F39,"000"),"_",$G39,"__",$E39) -> Update_Opt_Out_To_Unsubscriber_Preferences_Email_Ln000_DE__Unsubscriber_Preferences_Email | B39: =VLOOKUP($D39,Activities!$D:$G,3,FALSE) -> SQL | C39: =VLOOKUP($D39,Activities!$D:$G,2,FALSE) -> Update_Opt_Out_To_Unsubscriber_Preferences_Email | D39: 21.1__Update_Opt_Out_To_Unsubscriber_Preferences_Email__SQL | E39: Unsubscriber_Preferences_Email | F39: 0 | G39: DE | H39: TargetDE | I39: SQL | J39: Update | K39: TargetDE
A40: =CONCATENATE($C40,"_Ln",TEXT($F40,"000"),"_",$G40,"__",$E40) -> Update_Opt_Out_To_Unsubscriber_Preferences_Email_Ln036_DE__Subscriber_Preferences_Email | B40: =VLOOKUP($D40,Activities!$D:$G,3,FALSE) -> SQL | C40: =VLOOKUP($D40,Activities!$D:$G,2,FALSE) -> Update_Opt_Out_To_Unsubscriber_Preferences_Email | D40: 21.1__Update_Opt_Out_To_Unsubscriber_Preferences_Email__SQL | E40: Subscriber_Preferences_Email | F40: 36 | G40: DE | H40: Source | I40: SQL | J40: FROM | K40: PrimarySource
...

Sheet Automation Improvement Ideas
A1: IdeaID | B1: Target Automation / Query Name | C1: Component Type | D1: Current Pain Point / Redundancy | E1: Proposed Optimization | F1: Estimated Value & Business Impact | G1: Complexity | H1: Priority | I1: Proposed By | J1: Status
A2: OPT-001 | B2: A09B__Consent-Consent Updates | C2: SQL Query | D2: Steps 11.1 and 12.1 append to Audit_Preferences sequentially. | E2: Consolidate into a single SQL step utilizing a UNION ALL or left joins. | F2: Reduces Automation Step count, lowers processing time by ~3 minutes. | G2: Low | H2: High | I2: Ajeet Singh | J2: Under Review
A3: OPT-002 | B3: CentralizedFormProcessor-Extract | C3: Script Activity | D3: Executes repetitive lookup API calls inside a loop. | E3: Refactor looping script to leverage unified Content Blocks or WSProxy. | F3: Reduces Salesforce API limits footprint and downstream timeouts. | G3: Medium | H3: Medium | I3: Varsha Shelar | J3: Backlog

Sheet REFERENCE
A3: A_StartingSource | C3: ACTType | E3: ActID | F3: ActivityName | H3: DataType | I3: DataTypeID | J3: Column1 | L3: AutoID | M3: Automation Name | N3: AutomationTitle
A4: Schedule | C4: SQL | E4: {=_xlfn._xlws.SORT(_xlfn.UNIQUE(_xlfn._xlws.FILTER(Activities[ActID],Activities[ActID]<>"","")))} -> A_00.0_ | F4: {=_xlfn._xlws.SORT(_xlfn.UNIQUE(_xlfn._xlws.FILTER(Activities[ActivityName],Activities[ActivityName]<>"","")))} -> 1_Click_Unsubscribe_Remove_From_Subscriber_Preferences_Email_DE | H4: Salesforce Object | I4: OBJ | L4: {=_xlfn._xlws.SORT(_xlfn.UNIQUE(_xlfn._xlws.FILTER(Automations[AutoID],Automations[AutoID]<>"","")))} -> 01A | M4: {=_xlfn._xlws.SORT(_xlfn.UNIQUE(_xlfn._xlws.FILTER(Automations[Automation Name],Automations[Automation Name]<>"","")))} -> Admin-AuditLogMCFTP | N4: {=_xlfn._xlws.SORT(_xlfn.UNIQUE(_xlfn._xlws.FILTER(Automations[AutomationTitle],Automations[AutomationTitle]<>"","")))} -> A0000__Admin-AuditLogMCFTP
A5: FileDrop | C5: SCRIPT | E5: A09B_01.1_SQL | F5: Consent-ExpiredUnsubscribeAllLinkClicks | H5: Data Extension | I5: DE | L5: 09B | M5: Admin-AuditTrailMaster | N5: A0000__Admin-AuditTrailMaster
A6: Trigger | C6: EXTRACT | E6: A09B_02.1_SQL | F6: ConsentUpdates-ExpiredUnsubscribeLinkClicks_DataExtract | H6: WSProxy/API | I6: API | M6: Admin-AutomationMetadataReport | N6: A0000__Admin-AutomationMetadataReport
C7: SYSTEM | E7: A09B_03.1_Script | F7: Optin_from_Unsubscribe_From_All_Preferences | H7: Shared Data Extension | I7: SDE | M7: Admin-CLUfrom4BUs_CwoCA | N7: A0000__Admin-CLUfrom4BUs_CwoCA
C8: TRANSFER | E8: A09B_04.1_SQL | F8: 1_Click_Unsubscribe_IFD_OptintoOptOut | M8: Admin-ContactsWithoutChannelAddresses | N8: A0000__Admin-ContactsWithoutChannelAddresses
C9: IMPORT | E9: A09B_05.1_DataExtract | F9: Add 1-Click_Unsubscribe_To_RecordKeeper | M9: Admin-CRMAHealthCheck | N9: A0000__Admin-CRMAHealthCheck
C10: WAIT | E10: A09B_06.1_FileTransfer | F10: Add_Opt_Out_To_Audit_Preferences_From_Unsubscribe_From_All_DE | M10: Admin-DataView_General | N10: A0000__Admin-DataView_General
C11: VERIF | E11: A09B_07.1_DataImport | F11: Add_Opt_Out_To_Audit_Preferences_From_Unsubscribe_Pref_Email | M11: Admin-DEArchive | N11: A0000__Admin-DEArchive
E12: A09B_08.1_SQL | F12: Add_PrimaryEmailRecords_To_OptOut_From_Sales_Cloud | M12: Admin-DEsForDataCloudPOC | N12: A0000__Admin-DEsForDataCloudPOC
E13: A09B_09.1_SCRIPT | F13: Add_Sales_Cloud_Active_To_Audit_Preferences_For_Contacts | M13: Admin-DEV-DataViewsDaily | N13: A0000__Admin-DEV-DataViewsDaily
E14: A09B_10.1_SQL | F14: Add_Sales_Cloud_Active_To_Audit_Preferences_For_Leads | M14: Admin-EmailEngagedActivities_Cleanup | N14: A0000__Admin-EmailEngagedActivities_Cleanup
E15: A09B_11.1_SQL | F15: Add_Sales_Cloud_Active_To_Record_Keeper | M15: Admin-MCUsersDeactivatedNotification | N15: A0000__Admin-MCUsersDeactivatedNotification
E16: A09B_12.1_SQL | F16: Add_Sales_Cloud_Unsubscribe_To_RecordKeeper_Unsub_From_All_DE | M16: Admin-MetaDataCopy | N16: A0000__Admin-MetaDataCopy
E17: A09B_13.1_SQL | F17: Add_Sales_Cloud_Unsubscribe_To_RecordKeeper_Unsub_Pref_Email_DE | M17: Admin-NonEmailEngagedActivities_Cleanup | N17: A0000__Admin-NonEmailEngagedActivities_Cleanup
E18: A09B_14.1_WAIT | F18: Add_Unsubscribe_To_Audit_Preferences_From_Unsubscribe_Pref_Email | M18: Admin-NonEmailEngagedActivities-ArchivedCampaignValidateV1 | N18: A0000__Admin-NonEmailEngagedActivities-ArchivedCampaignValidateV1
E19: A09B_15.1_SQL | F19: Add_Unsubscribes_To_Audit_Preferences_From_Unsubscribe_From_All | M19: Admin-Reset_HeldActiveInvalidEmailMarketingCloud | N19: A0000__Admin-Reset_HeldActiveInvalidEmailMarketingCloud
E20: A09B_16.1_SQL | F20: Consent_Status_Pending | M20: AutomatedDeletion-DERecycleBinItems | N20: A0000__AutomatedDeletion-DERecycleBinItems
E21: A09B_17.1_SQL | F21: Consent_Status_Update | M21: AutomationName | N21: A0000__Campaign-General
E22: A09B_18.1_DataExtract | F22: Consent-UpdateProcessedData | M22: Campaign-General | N22: A0000__CampaignMember-CampaignHierarchyRollupCampaignMemberAdditions
E23: A09B_19.1_FileTransfer | F23: ConsentUpdates-ExpiredUnsubscribeLinkClicks_SubscriberImport | M23: CampaignMember-CampaignHierarchyRollupCampaignMemberAdditions | N23: A0000__CampaignMember-General
... E52: A09B_48.1_SQL | F52: WAIT - 5 MIN | M52: LinkedIn-FilterDEs | N52: A0000__LinkedIn-LeadsCollection
E53: A09B_49.1_SCRIPT | M53: LinkedIn-LeadsCollection | N53: A0000__LinkedIn-RefreshAccessToken
E54: A09B_50.1_SQL | M54: LinkedIn-RefreshAccessToken | N54: A0000__MarketingScore-AllSources
E55: A09B_51.1_SQL | M55: MarketingScore-AllSources | N55: A0000__Preference-AuditPreferenceEnrollmentUpdate
E56: A09B_52.1_SCRIPT | M56: Preference-AuditPreferenceEnrollmentUpdate | N56: A0000__Reporting-Active Handraisers - KPMG US Webform Submissions
E57: A09B_53.1_VERIF | M57: Reporting-Active Handraisers - KPMG US Webform Submissions | N57: A0000__Reporting-AllianceMarketing_UpdateMasterDE
M58: Reporting-AllianceMarketing_UpdateMasterDE | N58: A0000__Reporting-AlumniIneligibleDeceased_Import
M59: Reporting-AlumniIneligibleDeceased_Import | N59: A0000__Reporting-CCSTracker_UpdateMasterDE
M60: Reporting-CCSTracker_UpdateMasterDE | N60: A0000__Reporting-CMO-UpdateMasterDE
M61: Reporting-CMO-UpdateMasterDE | N61: A0000__Reporting-ConsumerGoodsTechnology-CGT-UpdateMasterDE
M62: Reporting-ConsumerGoodsTechnology-CGT-UpdateMasterDE | N62: A0000__Reporting-DemandWorks_UpdateMasterDE
M63: Reporting-DemandWorks_UpdateMasterDE | N63: A0000__Reporting-EloquaOrganic_UpdateMasterDE
M64: Reporting-EloquaOrganic_UpdateMasterDE | N64: A0000__Reporting-EmailEngagedActivities
M65: Reporting-EmailEngagedActivities | N65: A0000__Reporting-Entrepreneur_UpdateMasterDE
M66: Reporting-Entrepreneur_UpdateMasterDE | N66: A0000__Reporting-Erepublic_UpdateMasterDE
M67: Reporting-Erepublic_UpdateMasterDE | N67: A0000__Reporting-ExeEdu-OnlineClassCompletion
M68: Reporting-ExeEdu-OnlineClassCompletion | N68: A0000__Reporting-ExeEdu-Registration
M69: Reporting-ExeEdu-Registration | N69: A0000__Reporting-Facebook-FormSubmit
... M153: SyncDE-InternationalCounts | N153: A01A__AutomationName
...

Sheet Followup

Sheet Activities
A1: ActivityTitle | B1: ActID | C1: Step | D1: ActName | E1: ActivityName | F1: ActType | G1: AutomationTitle | H1: Annotations | I1: . | J1: ActKey | K1: ActLocation | L1: ActDesc | M1: AutoID | N1: .. | O1: TargetDE | P1: DataAction | Q1: PrimarySource | R1: FileName | S1: SFTPFolder | T1: AlertEmails2
A2: =CONCATENATE("A",M2,"_",C2,"_",F2,"_",E2) -> A09B_1.1_SQL_Flip_Unsubscribe_To_Active_For_Lead | B2: =CONCATENATE("A",Activities[[#This Row],[AutoID]],"_",TEXT(Activities[[#This Row],[Step]],"##00.0"),"_",Activities[[#This Row],[ActType]]) -> A09B_01.1_SQL | C2: 1.1 | D2: =CONCATENATE(Activities[[#This Row],[Step]],"__",Activities[[#This Row],[ActivityName]],"__",Activities[[#This Row],[ActType]]) -> 1.1__Flip_Unsubscribe_To_Active_For_Lead__SQL | E2: Flip_Unsubscribe_To_Active_For_Lead | F2: SQL | G2: A09B__Consent-Consent Updates | H2: This query retrieves records of leads who have an Opt In or Opt In Pending consent status in Sales Cloud, ensuring that their consent capture date is more recent than their last unsubscribe activity. | I2: . | J2: 4E65F724-8F10-41E4-995E-E0A1B2FB4188 | K2: Query/09. Preference/Preference-ConsentUpdates | M2: 09B | N2: . | O2: Flip_All_Subscriber_Unsubscribe_to_Active | P2: Overwrite | Q2: KPMG_Individual_Firm_Details__c_Salesforce_3
A3: =CONCATENATE("A",M3,"_",C3,"_",F3,"_",E3) -> A09B_2.1_SQL_Flip_Unsubscribe_To_Active_For_Contact | B3: =CONCATENATE("A",Activities[[#This Row],[AutoID]],"_",TEXT(Activities[[#This Row],[Step]],"##00.0"),"_",Activities[[#This Row],[ActType]]) -> A09B_02.1_SQL | C3: 2.1 | D3: =CONCATENATE(Activities[[#This Row],[Step]],"__",Activities[[#This Row],[ActivityName]],"__",Activities[[#This Row],[ActType]]) -> 2.1__Flip_Unsubscribe_To_Active_For_Contact__SQL | E3: Flip_Unsubscribe_To_Active_For_Contact | F3: SQL | G3: A09B__Consent-Consent Updates | H3: This query retrieves records of contacts who have Opt In or Opt In Pending consent status in Sales Cloud, ensuring that their consent capture date is more recent than their last unsubscribe activity. | I3: . | J3: F1C78A7E-C45B-477C-9D16-7623EB1BAF51 | K3: Query/09. Preference/Preference-ConsentUpdates | M3: 09B | N3: . | O3: Flip_All_Subscriber_Unsubscribe_to_Active | P3: Update | Q3: KPMG_Individual_Firm_Details__c_Salesforce_3
A4: =CONCATENATE("A",M4,"_",C4,"_",F4,"_",E4) -> A09B_3.1_Script_DeleteFromAutoSuppressionList | B4: =CONCATENATE("A",Activities[[#This Row],[AutoID]],"_",TEXT(Activities[[#This Row],[Step]],"##00.0"),"_",Activities[[#This Row],[ActType]]) -> A09B_03.1_Script | C4: 3.1 | D4: =CONCATENATE(Activities[[#This Row],[Step]],"__",Activities[[#This Row],[ActivityName]],"__",Activities[[#This Row],[ActType]]) -> 3.1__DeleteFromAutoSuppressionList__Script | E4: DeleteFromAutoSuppressionList | F4: Script | G4: A09B__Consent-Consent Updates | H4: Deletes email addresses from the Global Auto Suppression List when their Consent Status in Sales Cloud changes to Opt-In or Opt-In Pending. | I4: . | J4: c3c1fad6-c526-4bfc-810d-244e80a4873e | K4: Scripts | M4: 09B | N4: . | O4: Global_Suppression_List | P4: Delete | Q4: DE557EE5-8DD3-427F-8971-FECDA988830C
A5: =CONCATENATE("A",M5,"_",C5,"_",F5,"_",E5) -> A09B_4.1_SQL_Final_Flip_All_Subscribers_To_Unsubscribe_To_Active | B5: =CONCATENATE("A",Activities[[#This Row],[AutoID]],"_",TEXT(Activities[[#This Row],[Step]],"##00.0"),"_",Activities[[#This Row],[ActType]]) -> A09B_04.1_SQL | C5: 4.1 | D5: =CONCATENATE(Activities[[#This Row],[Step]],"__",Activities[[#This Row],[ActivityName]],"__",Activities[[#This Row],[ActType]]) -> 4.1__Final_Flip_All_Subscribers_To_Unsubscribe_To_Active__SQL | E5: Final_Flip_All_Subscribers_To_Unsubscribe_To_Active | F5: SQL | G5: A09B__Consent-Consent Updates | H5: This query selects email addresses and subscriber keys from Flip_All_Subscriber_Unsubscribe_to_Active DE and labels each record with a static status of Active. | I5: . | J5: B83D6529-E980-46F9-8D31-2356601FA751 | K5: Query/09. Preference/Preference-ConsentUpdates | L5: This query selects email addresses and subscriber keys from Flip_All_Subscriber_Unsubscribe_to_Active DE and labels each record with a static status of Active. | M5: 09B | N5: . | O5: Final_Flip_All_Subscriber_Unsubscribe_To_Active | P5: Overwrite | Q5: Flip_All_Subscriber_Unsubscribe_to_Active
A6: =CONCATENATE("A",M6,"_",C6,"_",F6,"_",E6) -> A09B_5.1_DataExtract_Final_Flip_All_Subscriber_Unsubscribe_to_Active | B6: =CONCATENATE("A",Activities[[#This Row],[AutoID]],"_",TEXT(Activities[[#This Row],[Step]],"##00.0"),"_",Activities[[#This Row],[ActType]]) -> A09B_05.1_DataExtract | C6: 5.1 | D6: =CONCATENATE(Activities[[#This Row],[Step]],"__",Activities[[#This Row],[ActivityName]],"__",Activities[[#This Row],[ActType]]) -> 5.1__Final_Flip_All_Subscriber_Unsubscribe_to_Active__DataExtract | E6: Final_Flip_All_Subscriber_Unsubscribe_to_Active | F6: DataExtract | G6: A09B__Consent-Consent Updates | H6: Extract records from Final_Flip_All_Subscriber_Unsubscribe_to_Active. | I6: . | J6: 2BEFA88C-6031-40C4-AEBE-F6EBBA934167 | L6: Extract records from Final_Flip_All_Subscriber_Unsubscribe_to_Active | M6: 09B | N6: . | O6: FILE | P6: Data Extension Extract | Q6: 83E395BE-50BB-4774-9BA6-3D99B3DE3DAD | R6: Final_Flip_All_Subscriber_Unsubscribe_To_Active.csv | S6: Safehouse
A7: =CONCATENATE("A",M7,"_",C7,"_",F7,"_",E7) -> A09B_6.1_FileTransfer_Final_Flip_All_Subscriber_Unsubscribe_to_Active _o _FTP | B7: =CONCATENATE("A",Activities[[#This Row],[AutoID]],"_",TEXT(Activities[[#This Row],[Step]],"##00.0"),"_",Activities[[#This Row],[ActType]]) -> A09B_06.1_FileTransfer | C7: 6.1 | D7: =CONCATENATE(Activities[[#This Row],[Step]],"__",Activities[[#This Row],[ActivityName]],"__",Activities[[#This Row],[ActType]]) -> 6.1__Final_Flip_All_Subscriber_Unsubscribe_to_Active _o _FTP__FileTransfer | E7: Final_Flip_All_Subscriber_Unsubscribe_to_Active _o _FTP | F7: FileTransfer | G7: A09B__Consent-Consent Updates | H7: FTP Final_Flip_All_Subscriber_Unsubscribe_to_Active.csv file transfer | I7: . | J7: 5b3abdae-fa3c-466f-8da6-7a34e32a212d | M7: 09B | N7: . | O7: FILE | P7: Move a File From Safehouse | Q7: Final_Flip_All_Subscriber_Unsubscribe_To_Active.csv | R7: Final_Flip_All_Subscriber_Unsubscribe_To_Active.csv | S7: KPMG SFTP Outgoing
A8: =CONCATENATE("A",M8,"_",C8,"_",F8,"_",E8) -> A09B_7.1_DataImport_Flip_All_Subscriber_Unsubscribe_to_Active | B8: =CONCATENATE("A",Activities[[#This Row],[AutoID]],"_",TEXT(Activities[[#This Row],[Step]],"##00.0"),"_",Activities[[#This Row],[ActType]]) -> A09B_07.1_DataImport | C8: 7.1 | D8: =CONCATENATE(Activities[[#This Row],[Step]],"__",Activities[[#This Row],[ActivityName]],"__",Activities[[#This Row],[ActType]]) -> 7.1__Flip_All_Subscriber_Unsubscribe_to_Active__DataImport | E8: Flip_All_Subscriber_Unsubscribe_to_Active | F8: DataImport | G8: A09B__Consent-Consent Updates | H8: Importing records to destination from ftp in All Subscribers List. | I8: . | J8: 16CA12A3-35CA-4103-9C8F-5CA92BE289BB | L8: Importing records to destination from ftp. | M8: 09B | N8: . | O8: "All Subscribers" (Subscriber List) | P8: Import_Update Only | Q8: Final_Flip_All_Subscriber_Unsubscribe_To_Active.csv | R8: Final_Flip_All_Subscriber_Unsubscribe_To_Active.csv | T8: NONE
A9: =CONCATENATE("A",M9,"_",C9,"_",F9,"_",E9) -> A09B_8.1_SQL_ Optin_from_Unsubscribe_From_All_Preferences | B9: =CONCATENATE("A",Activities[[#This Row],[AutoID]],"_",TEXT(Activities[[#This Row],[Step]],"##00.0"),"_",Activities[[#This Row],[ActType]]) -> A09B_08.1_SQL | C9: 8.1 | D9: =CONCATENATE(Activities[[#This Row],[Step]],"__",Activities[[#This Row],[ActivityName]],"__",Activities[[#This Row],[ActType]]) -> 8.1__ Optin_from_Unsubscribe_From_All_Preferences__SQL | E9: Optin_from_Unsubscribe_From_All_Preferences | F9: SQL | G9: A09B__Consent-Consent Updates | H9: Populate the Optin Records from Unsubscribe_From_All_Preferences DE | I9: . | J9: E10E206B-7F45-4092-80DD-D5BEC1E82CED | K9: Query/09. Preference/Preference-ConsentUpdates | M9: 09B | N9: . | O9: Remove_Optin_Records_From_UnsubscribeFromAllPreferences | P9: Overwrite | Q9: Flip_All_Subscriber_Unsubscribe_to_Active
A10: =CONCATENATE("A",M10,"_",C10,"_",F10,"_",E10) -> A09B_9.1_SCRIPT_Delete_Optin_UnsubAll | B10: =CONCATENATE("A",Activities[[#This Row],[AutoID]],"_",TEXT(Activities[[#This Row],[Step]],"##00.0"),"_",Activities[[#This Row],[ActType]]) -> A09B_09.1_SCRIPT | C10: 9.1 | D10: =CONCATENATE(Activities[[#This Row],[Step]],"__",Activities[[#This Row],[ActivityName]],"__",Activities[[#This Row],[ActType]]) -> 9.1__Delete_Optin_UnsubAll__SCRIPT | E10: Delete_Optin_UnsubAll | F10: SCRIPT | G10: A09B__Consent-Consent Updates | H10: Delete the records from Unsubscribe_From_All_Preferences DE | I10: . | J10: ec56d06d-55c0-4f9e-bdeb-4bdde2448ed4 | K10: Scripts/09. Preference/Consent Updates | M10: 09B | N10: . | O10: Unsubscribe_From_All_Preferences | P10: Delete/Update | Q10: 04F6B6B9-48F0-4DC9-B69C-C434A0ABC33F
A11: =CONCATENATE("A",M11,"_",C11,"_",F11,"_",E11) -> A09B_10.1_SQL_Remaining_OptIn_Records_From_Unsubscribe | B11: =CONCATENATE("A",Activities[[#This Row],[AutoID]],"_",TEXT(Activities[[#This Row],[Step]],"##00.0"),"_",Activities[[#This Row],[ActType]]) -> A09B_10.1_SQL | C11: 10.1 | D11: =CONCATENATE(Activities[[#This Row],[Step]],"__",Activities[[#This Row],[ActivityName]],"__",Activities[[#This Row],[ActType]]) -> 10.1__Remaining_OptIn_Records_From_Unsubscribe__SQL | E11: Remaining_OptIn_Records_From_Unsubscribe | F11: SQL | G11: A09B__Consent-Consent Updates | I11: . | J11: 9DBA23DE-D0EE-4492-9E98-FF6E31722933 | K11: Query/09. Preference | M11: 09B | N11: . | O11: Remaining_Optin_Records_From_UnsubscribeFromAllPreferences | P11: Overwrite | Q11: Remove_Optin_Records_From_UnsubscribeFromAllPreferences
A12: =CONCATENATE("A",M12,"_",C12,"_",F12,"_",E12) -> A09B_11.1_SQL_Add_Sales_Cloud_Active_To_Audit_Preferences_For_Leads | B12: =CONCATENATE("A",Activities[[#This Row],[AutoID]],"_",TEXT(Activities[[#This Row],[Step]],"##00.0"),"_",Activities[[#This Row],[ActType]]) -> A09B_11.1_SQL | C12: 11.1 | D12: =CONCATENATE(Activities[[#This Row],[Step]],"__",Activities[[#This Row],[ActivityName]],"__",Activities[[#This Row],[ActType]]) -> 11.1__Add_Sales_Cloud_Active_To_Audit_Preferences_For_Leads__SQL | E12: Add_Sales_Cloud_Active_To_Audit_Preferences_For_Leads | F12: SQL | G12: A09B__Consent-Consent Updates | H12: This query adds records of leads who opt in via Sales Cloud to the Audit_Preferences DE. | I12: . | J12: 1BD881AD-854D-496B-977B-18FE23DF8D40 | K12: Query/09. Preference/Preference-ConsentUpdates | L12: This query adds records of leads who opt in via Sales Cloud to the Audit_Preferences DE. | M12: 09B | N12: . | O12: Audit_Preferences | P12: Append | Q12: Flip_All_Subscriber_Unsubscribe_to_Active
A13: =CONCATENATE("A",M13,"_",C13,"_",F13,"_",E13) -> A09B_12.1_SQL_Add_Sales_Cloud_Active_To_Audit_Preferences_For_Contacts | B13: =CONCATENATE("A",Activities[[#This Row],[AutoID]],"_",TEXT(Activities[[#This Row],[Step]],"##00.0"),"_",Activities[[#This Row],[ActType]]) -> A09B_12.1_SQL | C13: 12.1 | D13: =CONCATENATE(Activities[[#This Row],[Step]],"__",Activities[[#This Row],[ActivityName]],"__",Activities[[#This Row],[ActType]]) -> 12.1__Add_Sales_Cloud_Active_To_Audit_Preferences_For_Contacts__SQL | E13: Add_Sales_Cloud_Active_To_Audit_Preferences_For_Contacts | F13: SQL | G13: A09B__Consent-Consent Updates | H13: This query adds records of contacts who opt in via Sales Cloud to the Audit_Preferences DE. | I13: . | J13: 3F83A884-CDA2-475B-9807-0503D877980E | K13: Query/09. Preference/Preference-ConsentUpdates | L13: This query adds records of contacts who opt in via Sales Cloud to the Audit_Preferences DE. | M13: 09B | N13: . | O13: Audit_Preferences | P13: Append | Q13: Flip_All_Subscriber_Unsubscribe_to_Active
A14: =CONCATENATE("A",M14,"_",C14,"_",F14,"_",E14) -> A09B_13.1_SQL_Add_Sales_Cloud_Active_To_Record_Keeper | B14: =CONCATENATE("A",Activities[[#This Row],[AutoID]],"_",TEXT(Activities[[#This Row],[Step]],"##00.0"),"_",Activities[[#This Row],[ActType]]) -> A09B_13.1_SQL | C14: 13.1 | D14: =CONCATENATE(Activities[[#This Row],[Step]],"__",Activities[[#This Row],[ActivityName]],"__",Activities[[#This Row],[ActType]]) -> 13.1__Add_Sales_Cloud_Active_To_Record_Keeper__SQL | E14: Add_Sales_Cloud_Active_To_Record_Keeper | F14: SQL | G14: A09B__Consent-Consent Updates | H14: This query adds records of subscribers who opt in via Sales Cloud to the ConsentUpdates_Recordkeeper DE | I14: . | J14: C7E06ED8-0E17-44E3-AC44-5B26C3825C90 | K14: Query/09. Preference/Preference-ConsentUpdates | L14: This query adds records of subscribers who opt in via Sales Cloud to the ConsentUpdates_Recordkeeper DE | M14: 09B | N14: . | O14: ConsentUpdates_Recordkeeper | P14: Append | Q14: Flip_All_Subscriber_Unsubscribe_to_Active
A15: =CONCATENATE("A",M15,"_",C15,"_",F15,"_",E15) -> A09B_14.1_WAIT_WAIT - 5 MIN | B15: =CONCATENATE("A",Activities[[#This Row],[AutoID]],"_",TEXT(Activities[[#This Row],[Step]],"##00.0"),"_",Activities[[#This Row],[ActType]]) -> A09B_14.1_WAIT | C15: 14.1 | D15: =CONCATENATE(Activities[[#This Row],[Step]],"__",Activities[[#This Row],[ActivityName]],"__",Activities[[#This Row],[ActType]]) -> 14.1__WAIT - 5 MIN__WAIT | E15: WAIT - 5 MIN | F15: WAIT | G15: A09B__Consent-Consent Updates | I15: . | J15: N/A | K15: N/A | L15: N/A | M15: 09B | N15: . | O15: N/A | P15: N/A | Q15: N/A
A16: =CONCATENATE("A",M16,"_",C16,"_",F16,"_",E16) -> A09B_15.1_SQL_Flip_Active_To_Unsubscribe_For_Lead | B16: =CONCATENATE("A",Activities[[#This Row],[AutoID]],"_",TEXT(Activities[[#This Row],[Step]],"##00.0"),"_",Activities[[#This Row],[ActType]]) -> A09B_15.1_SQL | C16: 15.1 | D16: =CONCATENATE(Activities[[#This Row],[Step]],"__",Activities[[#This Row],[ActivityName]],"__",Activities[[#This Row],[ActType]]) -> 15.1__Flip_Active_To_Unsubscribe_For_Lead__SQL | E16: Flip_Active_To_Unsubscribe_For_Lead | F16: SQL | G16: A09B__Consent-Consent Updates | H16: This query retrieves records of leads who have an Opt Out consent status in Sales Cloud, ensuring that their consent capture date is not null. | I16: . | J16: D8D21A53-D37E-4F40-9F4B-321E80FDFA52 | K16: Query/09. Preference/Preference-ConsentUpdates | M16: 09B | N16: . | O16: Preferences-Update_Unsubscribed_in_AllSubscribers | P16: Overwrite | Q16: KPMG_Individual_Firm_Details__c_Salesforce_3
A17: =CONCATENATE("A",M17,"_",C17,"_",F17,"_",E17) -> A09B_16.1_SQL_Flip_Active_To_Unsubscribe_For_Contact | B17: =CONCATENATE("A",Activities[[#This Row],[AutoID]],"_",TEXT(Activities[[#This Row],[Step]],"##00.0"),"_",Activities[[#This Row],[ActType]]) -> A09B_16.1_SQL | C17: 16.1 | D17: =CONCATENATE(Activities[[#This Row],[Step]],"__",Activities[[#This Row],[ActivityName]],"__",Activities[[#This Row],[ActType]]) -> 16.1__Flip_Active_To_Unsubscribe_For_Contact__SQL | E17: Flip_Active_To_Unsubscribe_For_Contact | F17: SQL | G17: A09B__Consent-Consent Updates | H17: This query retrieves records of contacts who have Opt Out consent status in Sales Cloud, ensuring that their consent capture date is not null. | I17: . | J17: 52F4B4BD-F015-465E-8481-DA0792C0137F | K17: Query/09. Preference/Preference-ConsentUpdates | M17: 09B | N17: . | O17: Preferences-Update_Unsubscribed_in_AllSubscribers | P17: Update | Q17: KPMG_Individual_Firm_Details__c_Salesforce_3
A18: =CONCATENATE("A",M18,"_",C18,"_",F18,"_",E18) -> A09B_17.1_SQL_Final_Preferences-Update_Unsubscribed_in_AllSubscribers | B18: =CONCATENATE("A",Activities[[#This Row],[AutoID]],"_",TEXT(Activities[[#This Row],[Step]],"##00.0"),"_",Activities[[#This Row],[ActType]]) -> A09B_17.1_SQL | C18: 17.1 | D18: =CONCATENATE(Activities[[#This Row],[Step]],"__",Activities[[#This Row],[ActivityName]],"__",Activities[[#This Row],[ActType]]) -> 17.1__Final_Preferences-Update_Unsubscribed_in_AllSubscribers__SQL | E18: Final_Preferences-Update_Unsubscribed_in_AllSubscribers | F18: SQL | G18: A09B__Consent-Consent Updates | H18: This query selects email addresses and subscriber keys from Preferences-Update_Unsubscribed_in_AllSubscribers DE and labels each record with a static status of Unsubscribed. | I18: . | J18: BBAEDF08-769E-43D5-BEF8-C905C1D65F85 | K18: Query/09. Preference/Preference-ConsentUpdates | L18: This query selects email addresses and subscriber keys from Preferences-Update_Unsubscribed_in_AllSubscribers DE and labels each record with a static status of Unsubscribed. | M18: 09B | N18: . | O18: Final_Preferences-Update_Unsubscribed_in_AllSubscribers | P18: Overwrite | Q18: Preferences-Update_Unsubscribed_in_AllSubscribers
A19: =CONCATENATE("A",M19,"_",C19,"_",F19,"_",E19) -> A09B_18.1_DataExtract_Unsubscribed_in_AllSubscribers_DataExtract | B19: =CONCATENATE("A",Activities[[#This Row],[AutoID]],"_",TEXT(Activities[[#This Row],[Step]],"##00.0"),"_",Activities[[#This Row],[ActType]]) -> A09B_18.1_DataExtract | C19: 18.1 | D19: =CONCATENATE(Activities[[#This Row],[Step]],"__",Activities[[#This Row],[ActivityName]],"__",Activities[[#This Row],[ActType]]) -> 18.1__Unsubscribed_in_AllSubscribers_DataExtract__DataExtract | E19: Unsubscribed_in_AllSubscribers_DataExtract | F19: DataExtract | G19: A09B__Consent-Consent Updates | H19: Extracts records from Preferences-Final_Preferences-Update_Unsubscribed_in_AllSubscribers Data Extension | I19: . | J19: F4F6C89B-018A-4FE8-A8EE-CE48D66BECA6 | L19: Extracts records from Preferences-Update_Unsubscribed_in_AllSubscribers Data Extension | M19: 09B | N19: . | O19: FILE | P19: Data Extension Extract | Q19: 322F755E-7A2E-4E11-A7E6-7284A1469F26 | R19: Active_to_Unsubscribed_in_AllSubscribers.csv
